<mujoco model="Robot">
  <compiler angle="radian" meshdir="./meshes"/>
  <option timestep="0.0005" integrator="RK4" />
  <extension>
    <plugin plugin="mujoco.pid">
      <instance name="rev1_pid">
        <config key="kp" value="20.0"/>
        <config key ="ki" value="10.0"/>
        <config key="kd" value="2"/>
        <config key="slewmax" value="3" />
        <config key="imax" value="1"/>
      </instance>
      <instance name="rev2_pid">
        <config key="kp" value="14.0"/>
        <config key ="ki" value="10.0"/>
        <config key="kd" value="5"/>
        <config key="slewmax" value="3" />
        <config key="imax" value="1"/>
      </instance>
      <instance name="rev3_pid">
        <config key="kp" value="20.0"/>
        <config key ="ki" value="10.0"/>
        <config key="kd" value="1"/>
        <config key="slewmax" value="3" />
        <config key="imax" value="1"/>
      </instance>
      <instance name="rev4_pid">
        <config key="kp" value="15.0"/>
        <config key ="ki" value="10.0"/>
        <config key="kd" value="1"/>
        <config key="slewmax" value="3" />
        <config key="imax" value="1"/>
      </instance>
      <instance name="rev5_pid">
        <config key="kp" value="15.0"/>
        <config key ="ki" value="10.0"/>
        <config key="kd" value="0.1"/>
        <config key="slewmax" value="3" />
        <config key="imax" value="1"/>
      </instance>
      <instance name="rev6_pid">
        <config key="kp" value="15.0"/>
        <config key ="ki" value="10.0"/>
        <config key="kd" value="0.01"/>
        <config key="slewmax" value="3" />
        <config key="imax" value="1"/>
      </instance>
      <!-- <instance name="rev7_pid">
        <config key="kp" value="40.0"/>
        <config key ="ki" value="20.0"/>
        <config key="kd" value="4"/>
        <config key="slewmax" value="3" />
        <config key="imax" value="1"/>
      </instance> -->
    </plugin>
  </extension>

  <asset>
    <texture type="2d" name="grid" builtin="checker" mark="edge" rgb1="0.1 0.2 0.3" rgb2="0.2 0.3 0.4" markrgb="0.2 0.3 0.4" width="300" height="300"/>
    <material name="grid" texture="grid" texuniform="true" reflectance="0.0"/>
  </asset>
  <worldbody>
    <geom size="0.0480723 0.0480723 0.0296" pos="0 0 -0.03" type="box"/>
    <body name="link1" pos="0 0 0.00">
      <inertial pos="0.00228623 -0.000216833 0.0275609" quat="0.525931 0.473613 0.486121 0.512615" mass="0.495525" diaginertia="0.000722477 0.000595661 0.000315904"/>
      <joint name="rev1" pos="0 0 0" axis="0 0 1" range="-2.356194 2.356194"/>
      <geom size="0.007 0.0294959 0.0355" pos="-0.034 0 0.03875" type="box"/>
      <geom size="0.005625 0.0294959 0.0355" pos="0.035375 0 0.03875" type="box"/>
      <body name="link2" pos="0.02975 0 0.04475" quat="0.5 -0.5 0.5 -0.5">
        <inertial pos="0.0474133 -0.0127813 -0.027" quat="0.453464 0.542559 0.453464 0.542559" mass="0.195626" diaginertia="9.04614e-05 7.98758e-05 5.99966e-05"/>
        <joint name="rev2" pos="0 0 0" axis="0 0 1" range="-3.14 0"/>
        <geom size="0.0315 0.0333159 0.032747" pos="0.0321835 -0.00889003 -0.027" quat="0.382527 -0.594704 -0.382527 -0.594704" type="box"/>
        <body name="link3" pos="0.0591625 -0.0158545 -0.027" quat="-0.701161 -0.0915019 -0.701161 0.0915019">
          <inertial pos="0.000118275 0.016179 0.122898" quat="0.502729 0.497444 -0.497459 0.502342" mass="0.305221" diaginertia="0.0016817 0.00153053 0.000240914"/>
          <joint name="rev3" pos="0 0 0" axis="0 0 1" range="-2.0944 2.0944"/>
          <geom size="0.0345 0.129124 0.0426943" pos="0 0.00119351 0.124124" quat="0.763222 0.646136 0 0" type="box"/>
          <body name="link4" pos="0.0270047 0 0.2455" quat="0.705031 -0.0541377 0.705031 -0.0541377">
            <inertial pos="0.0159771 -0.0239328 -0.0271701" quat="0.580447 0.411112 -0.466819 0.525498" mass="0.444319" diaginertia="0.00137305 0.000926782 0.000619899"/>
            <joint name="rev4" pos="0 0 0" axis="0 0 1" range="-2.0 0"/>
            <geom size="0.0410047 0.0852527 0.0393502" pos="0.0386491 -0.0413724 -0.0297547" quat="0.632391 0.316357 -0.632391 0.316357" type="box"/>
            <body name="link5" pos="0.0909178 -0.101815 -0.0297547" quat="0.645424 -0.288838 -0.645424 -0.288838">
              <inertial pos="-0.000903569 -0.00156057 -0.0298803" quat="0.587464 0.432339 -0.433524 0.529175" mass="0.263679" diaginertia="0.000483653 0.000368144 0.000203888"/>
              <joint name="rev5" pos="0 0 0" axis="0 0 1" range="-2.0944 2.0944"/>
              <geom size="0.04015 0.0678986 0.0330344" pos="0.00065 0.00664939 -0.0602639" quat="0.634004 0.77333 0 0" type="box"/>
              <body name="link6" pos="0.0355 0 -0.12105" quat="0.703667 0.0696631 0.703667 0.0696631">
                <inertial pos="0.00603009 0.000195868 -0.0339849" quat="0.292252 0.646217 0.295416 0.640095" mass="0.0392424" diaginertia="4.33169e-05 4.20513e-05 5.73168e-06"/>
                <joint name="rev6" pos="0 0 0" axis="0 0 1" range="-0.3 1.5708"/>
                <geom size="0.0413 0.0250181 0.0164941" pos="0.0068895 0.000417693 -0.034" quat="0 0.707107 0 0.707107" type="box"/>
              </body>
            </body>
          </body>
        </body>
      </body>
    </body>
    <geom name="ground" size="0.5 0.5 0.1" type="plane" material="grid"/>
  </worldbody>
  <actuator>
    <plugin joint="rev1" name="rev1_actuator" plugin="mujoco.pid" instance="rev1_pid" actdim="2" ctrllimited="true" ctrlrange="-2.356194 2.356194"/>
    <plugin joint="rev2" name="rev2_actuator" plugin="mujoco.pid" instance="rev2_pid" actdim="2" ctrllimited="true" ctrlrange="-3.14 0"/>
    <plugin joint="rev3" name="rev3_actuator" plugin="mujoco.pid" instance="rev3_pid" actdim="2" ctrllimited="true" ctrlrange="-2.0944 2.0944"/>
    <plugin joint="rev4" name="rev4_actuator" plugin="mujoco.pid" instance="rev4_pid" actdim="2" ctrllimited="true" ctrlrange="-2.0 0"/>
    <plugin joint="rev5" name="rev5_actuator" plugin="mujoco.pid" instance="rev5_pid" actdim="2" ctrllimited="true" ctrlrange="-2.0944 2.0944"/>
    <plugin joint="rev6" name="rev6_actuator" plugin="mujoco.pid" instance="rev6_pid" actdim="2" ctrllimited="true" ctrlrange="-0.3 1.5708"/>
    <!-- <plugin joint="rev7" name="rev7_actuator" plugin="mujoco.pid" instance="rev7_pid" actdim="2" ctrllimited="true" ctrlrange="-0.5 0.5"/> -->
    <!-- <position name="gripper_actuator" tendon="split" kv="20.5" kp="100.0" ctrllimited="true" ctrlrange="-0.0455 0"/> -->
  </actuator>
</mujoco>
