<!--
Copyright 2026 Enactic, Inc.

Licensed under the Apache License, Version 2.0 (the "License");
you may not use this file except in compliance with the License.
You may obtain a copy of the License at

    http://www.apache.org/licenses/LICENSE-2.0

Unless required by applicable law or agreed to in writing, software
distributed under the License is distributed on an "AS IS" BASIS,
WITHOUT WARRANTIES OR CONDITIONS OF ANY KIND, either express or implied.
See the License for the specific language governing permissions and
limitations under the License.
-->

<!--
Valve: a fixed pipe with a turnable lever (revolute joint) on a table, with a
graspable knob at the lever tip and inactive grasp welds for either arm.
-->
<mujoco model="openarm_v20_valve">
  <compiler meshdir="assets" angle="radian"/>

  <default>
    <default class="fixture">
      <geom type="box" contype="1" conaffinity="1" friction="1 0.01 0.01" rgba="0.55 0.45 0.32 1"/>
    </default>
  </default>

  <statistic center="0.30 0 0.55" extent="1.2" meansize="0.05"/>
  <option timestep="0.001"/>

  <visual>
    <headlight diffuse="0.6 0.6 0.6" ambient="0.3 0.3 0.3" specular="0 0 0"/>
    <rgba haze="0.15 0.25 0.35 1"/>
    <global azimuth="150" elevation="-20"/>
    <quality shadowsize="8192"/>
  </visual>

  <asset>
    <texture type="skybox" builtin="gradient" rgb1="0.55 0.55 0.58" rgb2="0.2 0.2 0.2" width="512" height="3072"/>
    <texture type="2d" name="groundplane" builtin="checker" mark="edge" rgb1="0.38 0.38 0.4" rgb2="0.3 0.3 0.32"
      markrgb="0.6 0.6 0.6" width="300" height="300"/>
    <material name="groundplane" texture="groundplane" texuniform="true" texrepeat="5 5" reflectance="0.2"/>

    <model name="arm_pedestal" file="openarm_pedestal.xml"/>
  </asset>

  <worldbody>
    <light pos="0 0 2" dir="0 0 -1" directional="true"/>
    <geom name="floor" size="0 0 0.05" type="plane" material="groundplane"/>

    <camera name="tablecam" pos="0.30 0.0 1.30" xyaxes="1 0 0 0 1 0" fovy="60"/>
    <camera name="frontcam" pos="1.05 0.0 0.90" xyaxes="0 -1 0 0.3 0 1" fovy="55"/>

    <!-- bimanual arms mounted on the pedestal -->
    <attach model="arm_pedestal" prefix=""/>

    <!-- Table: top at z=0.40, centered on the arm (y=0). Footprint matches the
         cell workspace table in cell.xml (0.41 x 0.55 half-extents) so tabletop
         layouts carry over; the cell mounts the arms on a lifter above the
         table, so absolute heights differ. -->
    <body name="table" pos="0.47 0.0 0.36">
      <geom name="table_top" type="box" size="0.41 0.55 0.04" rgba="0.82 0.71 0.55 1"
            friction="1 0.005 0.0001" contype="1" conaffinity="1"/>
    </body>

    <!-- VALVE: a fixed pipe with a lever that turns about the vertical axis; grasp
         the knob at the lever tip and sweep it in an arc. -->
    <body name="valve_base" pos="0.25 0.0 0.40">
      <geom name="valve_pipe" class="fixture" type="cylinder" size="0.015 0.0275" pos="0 0 0.0275" rgba="0.4 0.4 0.45 1"/>
      <body name="valve" pos="0 0 0.065">
        <joint name="valve_turn" type="hinge" axis="0 0 1" range="-3.0 3.0" damping="0.5" frictionloss="0.05"/>
        <geom name="valve_hub"   type="cylinder" fromto="0 0 -0.006 0 0 0.006" size="0.014" mass="0.05" rgba="0.3 0.3 0.35 1" contype="1" conaffinity="1"/>
        <geom name="valve_lever" type="box" size="0.035 0.008 0.006" pos="0.035 0 0" mass="0.05" rgba="0.7 0.2 0.2 1" contype="1" conaffinity="1"/>
        <geom name="valve_grip"  type="cylinder" fromto="0.062 0 -0.02 0.062 0 0.02" size="0.007" mass="0.02" rgba="0.2 0.2 0.22 1" contype="1" conaffinity="1"/>
      </body>
    </body>

  </worldbody>

  <equality>
    <weld name="grasp_right_valve" body1="openarm_right_ee_base_link" body2="valve" active="false" solref="0.02 1"/>
    <weld name="grasp_left_valve"  body1="openarm_left_ee_base_link"  body2="valve" active="false" solref="0.02 1"/>
  </equality>

  <keyframe>
    <!-- nq = left arm(0-8) + right arm(9-17) + valve(18) = 19.
         Arms at the shared "home" pose (same as pedestal.xml, with ctrl set so
         the position actuators hold it); valve closed. -->
    <key name="home"
      qpos="0.0 0.0 0.0 1.570796 0.0 0.0 0.0 0.0 0.0
            0.0 0.0 0.0 1.570796 0.0 0.0 0.0 0.0 0.0
            0"
      ctrl="0 0 0 1.570796 0 0 0 0
            0 0 0 1.570796 0 0 0 0"/>
  </keyframe>

</mujoco>
